Workbook

Sheet Sommaire
A1: Plans repas — 9 semaines indépendantes — 24 recettes — Chronodrive Compiègne, retrait le dimanche — budget midi + soir ≤ 55 €
A2: Modèle : dimanche soir pizza ; lundi → vendredi soir 5 recettes cuisinées en double portion (midi du lendemain) ; samedi soir + dimanche midi = 1 plat surgelé 900 g coupé en deux. 2 articles au congélateur maximum. Chaque recette au plus 2 fois sur 9 semaines, jamais 2 semaines de suite. Placard/bases comptés au PRIX PLEIN. S1 = inchangée (panier déjà fait). Prix Chronodrive relevés les 01-02/09/2026 ; pesto vert et sauce tomate-basilic estimés (relevés Carrefour Bomerée du 12/10 en note).
A4: Semaine | B4: Recettes (lundi → vendredi) | C4: Plat week-end | D4: Pizza | E4: Courses recettes (formats entiers) € | F4: Placard / bases prix plein € | G4: Week-end € | H4: TOTAL € | I4: Marge vs 55 € | J4: Gâchis estimé € | K4: Stock sec € | L4: kcal moyen / portion | M4: Prot moy. g | N4: Gluc moy. g | O4: Lip moy. g
A5: S1 | B5: 10. Côtes d'échine à la moutarde et à la crème + spaghetti · 16. « Couscous » étudiant poulet, carottes, pois chiches · 5. Pâtes à la « carbonara » à la française · 9. Riz au chorizo et poivrons (façon paella express) · 15. Saucisses-lentilles express (lentilles en conserve) | C5: Auchan Poulet basquaise et riz 900 g | D5: Auchan Pizza royale jambon-fromage-olives 400 g | E5: 28.03 | F5: 12.73 | G5: 6.9 | H5: 47.66 | I5: 7.34 | J5: 2.1451274 | K5: 6.7834284 | L5: =ROUND(AVERAGE(Nutrition!H71,Nutrition!H135,Nutrition!H148,Nutrition!H235,Nutrition!H253),0) -> 813 | M5: =AVERAGE(Nutrition!I71,Nutrition!I135,Nutrition!I148,Nutrition!I235,Nutrition!I253) -> 35.598 | N5: =AVERAGE(Nutrition!J71,Nutrition!J135,Nutrition!J148,Nutrition!J235,Nutrition!J253) -> 78.371 | O5: =AVERAGE(Nutrition!K71,Nutrition!K135,Nutrition!K148,Nutrition!K235,Nutrition!K253) -> 38.627
A6: S2 | B6: 3. Croque-monsieur express · 2. Gnocchis aux épinards, crème et lardons · 22. Frittata d'été aux courgettes et mozzarella filante (+ pain) · 21. Risotto de coquillettes au jambon, petits pois et parmesan · 24. Pâtes sauce tomate-basilic, mozzarella fondante & parmesan | C6: Auchan Penne poulet-champignons 900 g | D6: Ristorante 4 fromages 340 g | E6: 29.93 | F6: 7.62 | G6: 7.54 | H6: 45.09 | I6: 9.91 | J6: 2.2685738 | K6: 5.1177186 | L6: =ROUND(AVERAGE(Nutrition!H29,Nutrition!H41,Nutrition!H339,Nutrition!H356,Nutrition!H382),0) -> 771 | M6: =AVERAGE(Nutrition!I29,Nutrition!I41,Nutrition!I339,Nutrition!I356,Nutrition!I382) -> 36.252 | N6: =AVERAGE(Nutrition!J29,Nutrition!J41,Nutrition!J339,Nutrition!J356,Nutrition!J382) -> 82.123 | O6: =AVERAGE(Nutrition!K29,Nutrition!K41,Nutrition!K339,Nutrition!K356,Nutrition!K382) -> 31.778
A7: S3 | B7: 10. Côtes d'échine à la moutarde et à la crème + spaghetti · 12. Ravioli poêlés à la tomate et mozzarella · 23. Pâtes pesto caprese (boule de mozzarella, tomates cerises) · 1. Poulet au curry, lait de coco et noix de cajou + riz · 7. Quesadillas chorizo-emmental & avocat (version éco) | C7: Marie Lasagnes à la bolognaise 1 kg | D7: Auchan Pizza au chèvre 390 g | E7: 32.22 | F7: 14.63 | G7: 8.28 | H7: 55.13 | I7: -0.13 | J7: 2.4149003 | K7: 4.5582145 | L7: =ROUND(AVERAGE(Nutrition!H15,Nutrition!H105,Nutrition!H148,Nutrition!H186,Nutrition!H369),0) -> 933 | M7: =AVERAGE(Nutrition!I15,Nutrition!I105,Nutrition!I148,Nutrition!I186,Nutrition!I369) -> 40.96 | N7: =AVERAGE(Nutrition!J15,Nutrition!J105,Nutrition!J148,Nutrition!J186,Nutrition!J369) -> 77.294 | O7: =AVERAGE(Nutrition!K15,Nutrition!K105,Nutrition!K148,Nutrition!K186,Nutrition!K369) -> 49.991
A8: S4 | B8: 16. « Couscous » étudiant poulet, carottes, pois chiches · 24. Pâtes sauce tomate-basilic, mozzarella fondante & parmesan · 9. Riz au chorizo et poivrons (façon paella express) · 19. Pâtes crémeuses au chèvre, miel et lardons · 15. Saucisses-lentilles express (lentilles en conserve) | C8: Auchan Torsades à la carbonara 900 g | D8: Auchan Pizza bolognaise 390 g | E8: 27.13 | F8: 14.92 | G8: 7 | H8: 49.05 | I8: 5.95 | J8: 2.6259318 | K8: 5.8723765 | L8: =ROUND(AVERAGE(Nutrition!H135,Nutrition!H235,Nutrition!H253,Nutrition!H304,Nutrition!H382),0) -> 799 | M8: =AVERAGE(Nutrition!I135,Nutrition!I235,Nutrition!I253,Nutrition!I304,Nutrition!I382) -> 35.179 | N8: =AVERAGE(Nutrition!J135,Nutrition!J235,Nutrition!J253,Nutrition!J304,Nutrition!J382) -> 83.754 | O8: =AVERAGE(Nutrition!K135,Nutrition!K235,Nutrition!K253,Nutrition!K304,Nutrition!K382) -> 34.877
A9: S5 | B9: 13. Tortellini aux champignons, sauce crème-parmesan · 21. Risotto de coquillettes au jambon, petits pois et parmesan · 5. Pâtes à la « carbonara » à la française · 14. Risotto aux lardons et champignons · 20. One pot pasta chorizo-basilic | C9: Auchan Riz cantonais 900 g | D9: Auchan Les Italiennes 4 fromages 340 g | E9: 30.64 | F9: 12.78 | G9: 7.2 | H9: 50.62 | I9: 4.38 | J9: 3.1223049 | K9: 6.8326637 | L9: =ROUND(AVERAGE(Nutrition!H71,Nutrition!H204,Nutrition!H221,Nutrition!H321,Nutrition!H339),0) -> 878 | M9: =AVERAGE(Nutrition!I71,Nutrition!I204,Nutrition!I221,Nutrition!I321,Nutrition!I339) -> 33.655 | N9: =AVERAGE(Nutrition!J71,Nutrition!J204,Nutrition!J221,Nutrition!J321,Nutrition!J339) -> 98.615 | O9: =AVERAGE(Nutrition!K71,Nutrition!K204,Nutrition!K221,Nutrition!K321,Nutrition!K339) -> 37.593
A10: S6 | B10: 3. Croque-monsieur express · 8. Pâtes au pesto rosso et au poulet (+ parmesan) · 12. Ravioli poêlés à la tomate et mozzarella · 22. Frittata d'été aux courgettes et mozzarella filante (+ pain) · 1. Poulet au curry, lait de coco et noix de cajou + riz | C10: Auchan Paëlla poulet-crevettes-chorizo 900 g | D10: Auchan Pizza chorizo-poivrons 390 g | E10: 34.38 | F10: 12.42 | G10: 8.04 | H10: 54.84 | I10: 0.16 | J10: 3.7117794 | K10: 4.5979572 | L10: =ROUND(AVERAGE(Nutrition!H15,Nutrition!H41,Nutrition!H119,Nutrition!H186,Nutrition!H356),0) -> 843 | M10: =AVERAGE(Nutrition!I15,Nutrition!I41,Nutrition!I119,Nutrition!I186,Nutrition!I356) -> 42.508 | N10: =AVERAGE(Nutrition!J15,Nutrition!J41,Nutrition!J119,Nutrition!J186,Nutrition!J356) -> 76.049 | O10: =AVERAGE(Nutrition!K15,Nutrition!K41,Nutrition!K119,Nutrition!K186,Nutrition!K356) -> 39.597
A11: S7 | B11: 11. Raviolis frais à la sauce tomate-crème (poivron, épices) · 13. Tortellini aux champignons, sauce crème-parmesan · 18. Chakchouka au chèvre frais & pains pita · 14. Risotto aux lardons et champignons · 20. One pot pasta chorizo-basilic | C11: Bonduelle Poêlée gnocchi-épinards 750 g | D11: Ristorante margherita 355 g | E11: 34.04 | F11: 25.62 | G11: 7.04 | H11: 66.7 | I11: -11.7 | J11: 4.6653826 | K11: 5.2749642 | L11: =ROUND(AVERAGE(Nutrition!H171,Nutrition!H204,Nutrition!H221,Nutrition!H289,Nutrition!H321),0) -> 893 | M11: =AVERAGE(Nutrition!I171,Nutrition!I204,Nutrition!I221,Nutrition!I289,Nutrition!I321) -> 33.821 | N11: =AVERAGE(Nutrition!J171,Nutrition!J204,Nutrition!J221,Nutrition!J289,Nutrition!J321) -> 94.804 | O11: =AVERAGE(Nutrition!K171,Nutrition!K204,Nutrition!K221,Nutrition!K289,Nutrition!K321) -> 40.819
A12: S8 | B12: 4. Hachis parmentier rapide (purée en flocons) · 2. Gnocchis aux épinards, crème et lardons · 8. Pâtes au pesto rosso et au poulet (+ parmesan) · 23. Pâtes pesto caprese (boule de mozzarella, tomates cerises) · 7. Quesadillas chorizo-emmental & avocat (version éco) | C12: Auchan Poêlée campagnarde 900 g | D12: Auchan Pizza poulet barbecue 390 g | E12: 39.93 | F12: 5.64 | G12: 7.94 | H12: 53.51 | I12: 1.49 | J12: 4.9297466 | K12: 6.6022277 | L12: =ROUND(AVERAGE(Nutrition!H29,Nutrition!H58,Nutrition!H105,Nutrition!H119,Nutrition!H369),0) -> 903 | M12: =AVERAGE(Nutrition!I29,Nutrition!I58,Nutrition!I105,Nutrition!I119,Nutrition!I369) -> 40.615 | N12: =AVERAGE(Nutrition!J29,Nutrition!J58,Nutrition!J105,Nutrition!J119,Nutrition!J369) -> 77.009 | O12: =AVERAGE(Nutrition!K29,Nutrition!K58,Nutrition!K105,Nutrition!K119,Nutrition!K369) -> 47.476
A13: S9 | B13: 6. Poulet à la crème et aux champignons + spaghetti · 11. Raviolis frais à la sauce tomate-crème (poivron, épices) · 17. Poulet basquaise et son riz · 18. Chakchouka au chèvre frais & pains pita · 19. Pâtes crémeuses au chèvre, miel et lardons | C13: Bonduelle Poêlée gnocchi-tomate 750 g | D13: Auchan Pizza royale jambon-fromage-olives 400 g | E13: 37.18 | F13: 25.92 | G13: 6.14 | H13: 69.24 | I13: -14.24 | J13: 6.1870251 | K13: 6.5531786 | L13: =ROUND(AVERAGE(Nutrition!H90,Nutrition!H171,Nutrition!H271,Nutrition!H289,Nutrition!H304),0) -> 810 | M13: =AVERAGE(Nutrition!I90,Nutrition!I171,Nutrition!I271,Nutrition!I289,Nutrition!I304) -> 39.574 | N13: =AVERAGE(Nutrition!J90,Nutrition!J171,Nutrition!J271,Nutrition!J289,Nutrition!J304) -> 89.92 | O13: =AVERAGE(Nutrition!K90,Nutrition!K171,Nutrition!K271,Nutrition!K289,Nutrition!K304) -> 31.424

Sheet Étapes (2 portions)
A1: Étapes complètes des 24 recettes — QUANTITÉS POUR 2 PORTIONS — substitutions éco intégrées
A3: 1. Poulet au curry, lait de coco et noix de cajou + riz
A4: Source | B4: Marmiton — https://www.marmiton.org/recettes/recette_poulet-au-curry-lait-de-coco-et-noix-de-cajou_37398.aspx
A5: Temps | B5: 25 min (10 + 15)
A6: Ustensiles | B6: Sauteuse + casserole
A7: Substitutions | B7: aucune
A8: Ingrédients (2 portions) | B8: Qté | C8: Unité | D8: Équivalent | E8: Produit Chronodrive | F8: Origine
A9: Filet de poulet | B9: 260 | C9: g | D9: 1 filet | E9: Filets de poulet | F9: recette
A10: Lait de coco | B10: 200 | C10: ml | D10: ½ brique de 20 cl | E10: Lait de coco | F10: recette
A11: Curry en poudre | B11: 4 | C11: g | D11: 1 cc rase | E11: Curry en poudre Ducros 47 g | F11: placard
A12: Sauce soja | B12: 10 | C12: ml | D12: 1 cc | E12: Sauce soja | F12: recette
A13: Noix de cajou grillées salées | B13: 40 | C13: g | D13: 1 petite poignée | E13: Noix de cajou | F13: recette
A14: Maïzena | B14: 10 | C14: g | D14: 1 cc bombée | E14: Farine T45 | F14: placard
A15: Huile | B15: 30 | C15: ml | D15: 1 cs | E15: Huile de tournesol | F15: placard
A16: Riz long cru | B16: 160 | C16: g | D16: ½ verre | E16: Riz long | F16: ajout
A17: Sel | B17: 2 | C17: g | D17: 1 pincée | E17: Sel / poivre | F17: placard
A18: Poivre | B18: 1 | C18: g | D18: 1 tour de moulin | E18: Sel / poivre | F18: placard
A19: Étape | B19: Consigne (2 portions)
A20: 1 | B20: Riz : verser 160 g de riz long dans une casserole avec 240 ml d'eau et 1 pincée de sel. Porter à ébullition, couvrir, baisser à feu doux, cuire 11 min sans soulever le couvercle, puis couper le feu et laisser reposer 5 min à couvert.
A21: 2 | B21: Concasser 40 g de noix de cajou (fond d'un verre dans une assiette creuse) : moitié poudre, moitié petits morceaux.
A22: 3 | B22: Couper 260 g de filet de poulet en cubes de 1-2 cm. Les mettre dans un bol avec 10 g de farine (2 cc) et mélanger pour les enrober.
A23: 4 | B23: Chauffer 30 ml d'huile (2 cs) dans une sauteuse à feu moyen-vif. Ajouter 4 g de curry (2 cc) et laisser chauffer 30 s jusqu'à ce que ça sente.
A24: 5 | B24: Ajouter le poulet, faire dorer 5 min en remuant.
A25: 6 | B25: Verser 10 ml de sauce soja (2 cc) puis 200 ml de lait de coco (1 brique). Mélanger, baisser à feu doux, laisser cuire 10 min : la sauce épaissit grâce à la farine.
A26: 7 | B26: 5 min avant la fin, ajouter les noix de cajou. Saler légèrement, poivrer.
A27: 8 | B27: Servir la moitié sur la moitié du riz. Laisser refroidir l'autre moitié (riz et sauce séparés) avant de mettre en boîte au frigo pour le lendemain midi.
A29: 2. Gnocchis aux épinards, crème et lardons
A30: Source | B30: Marmiton — https://www.marmiton.org/recettes/recette_gnocchi-aux-epinards-creme-et-lardons_537272.aspx
A31: Temps | B31: 12 min (5 + 7)
A32: Ustensiles | B32: Casserole + poêle
A33: Substitutions | B33: aucune
A34: Ingrédients (2 portions) | B34: Qté | C34: Unité | D34: Équivalent | E34: Produit Chronodrive | F34: Origine
A35: Gnocchis (frais, à poêler ou à pocher) | B35: 500 | C35: g | D35: ½ paquet de 500 g | E35: Gnocchis à poêler | F35: recette
A36: Oignon | B36: 100 | C36: g | D36: ½ oignon moyen | E36: Oignons jaunes | F36: recette
A37: Lardons fumés | B37: 120 | C37: g | D37: ½ sachet de 100 g + un peu | E37: Lardons fumés | F37: recette
A38: Parmesan râpé (ou emmental) | B38: 40 | C38: g | D38: 2 cs | E38: Emmental râpé | F38: recette
A39: Crème liquide | B39: 200 | C39: ml | D39: ½ brique de 20 cl | E39: Crème liquide UHT | F39: recette
A40: Pousses d'épinards | B40: 100 | C40: g | D40: 2 grosses poignées | E40: Pousses d'épinard | F40: recette
A41: Sel | B41: 2 | C41: g | D41: 1 pincée | E41: Sel / poivre | F41: placard
A42: Poivre | B42: 1 | C42: g | E42: Sel / poivre | F42: placard
...

Sheet Nutrition
A1: Nutrition — estimation ingrédient par ingrédient, 1 PORTION (Ciqual / étiquettes pour 100 g ou 100 ml). Colonnes bleues = données saisies.
A3: 1. Poulet au curry, lait de coco et noix de cajou + riz
A4: Ingrédient | B4: Qté / portion | C4: Unité | D4: kcal/100 | E4: Prot/100 | F4: Gluc/100 | G4: Lip/100 | H4: kcal | I4: Protéines g | J4: Glucides g | K4: Lipides g | L4: Contrôle
A5: Filet de poulet | B5: 130 | C5: g | D5: 110 | E5: 23 | F5: 0 | G5: 2 | H5: =B5*D5/100 -> 143 | I5: =B5*E5/100 -> 29.9 | J5: =B5*F5/100 -> 0 | K5: =B5*G5/100 -> 2.6
A6: Lait de coco | B6: 100 | C6: ml | D6: 180 | E6: 1.5 | F6: 3 | G6: 18 | H6: =B6*D6/100 -> 180 | I6: =B6*E6/100 -> 1.5 | J6: =B6*F6/100 -> 3 | K6: =B6*G6/100 -> 18
A7: Curry en poudre | B7: 2 | C7: g | D7: 330 | E7: 12 | F7: 40 | G7: 12 | H7: =B7*D7/100 -> 6.6 | I7: =B7*E7/100 -> 0.24 | J7: =B7*F7/100 -> 0.8 | K7: =B7*G7/100 -> 0.24
A8: Sauce soja | B8: 5 | C8: ml | D8: 60 | E8: 6 | F8: 6 | G8: 0 | H8: =B8*D8/100 -> 3 | I8: =B8*E8/100 -> 0.3 | J8: =B8*F8/100 -> 0.3 | K8: =B8*G8/100 -> 0
A9: Noix de cajou grillées salées | B9: 20 | C9: g | D9: 600 | E9: 18 | F9: 22 | G9: 48 | H9: =B9*D9/100 -> 120 | I9: =B9*E9/100 -> 3.6 | J9: =B9*F9/100 -> 4.4 | K9: =B9*G9/100 -> 9.6
A10: Maïzena | B10: 5 | C10: g | D10: 350 | E10: 10 | F10: 72 | G10: 1 | H10: =B10*D10/100 -> 17.5 | I10: =B10*E10/100 -> 0.5 | J10: =B10*F10/100 -> 3.6 | K10: =B10*G10/100 -> 0.05
A11: Huile | B11: 15 | C11: ml | D11: 900 | E11: 0 | F11: 0 | G11: 100 | H11: =B11*D11/100 -> 135 | I11: =B11*E11/100 -> 0 | J11: =B11*F11/100 -> 0 | K11: =B11*G11/100 -> 15
A12: Riz long cru | B12: 80 | C12: g | D12: 350 | E12: 7 | F12: 78 | G12: 0.6 | H12: =B12*D12/100 -> 280 | I12: =B12*E12/100 -> 5.6 | J12: =B12*F12/100 -> 62.4 | K12: =B12*G12/100 -> 0.48
A13: Sel | B13: 1 | C13: g | D13: 0 | E13: 0 | F13: 0 | G13: 0 | H13: =B13*D13/100 -> 0 | I13: =B13*E13/100 -> 0 | J13: =B13*F13/100 -> 0 | K13: =B13*G13/100 -> 0
A14: Poivre | B14: 0.5 | C14: g | D14: 0 | E14: 0 | F14: 0 | G14: 0 | H14: =B14*D14/100 -> 0 | I14: =B14*E14/100 -> 0 | J14: =B14*F14/100 -> 0 | K14: =B14*G14/100 -> 0
A15: TOTAL 1 PORTION | H15: =SUM(H5:H14) -> 885.1 | I15: =SUM(I5:I14) -> 41.64 | J15: =SUM(J5:J14) -> 74.5 | K15: =SUM(K5:K14) -> 45.97 | L15: =IF(H15>=700,"≥ 700 kcal OK","< 700 kcal") -> ≥ 700 kcal OK
A16: x2 (dîner + midi lendemain) | H16: =H15*2 -> 1770.2 | I16: =I15*2 -> 83.28 | J16: =J15*2 -> 149 | K16: =K15*2 -> 91.94
A17: % de l'énergie (P / G / L) | I17: =I15*4/H15 -> 0.18818213 | J17: =J15*4/H15 -> 0.33668512 | K17: =K15*9/H15 -> 0.46743871
A19: 2. Gnocchis aux épinards, crème et lardons
A20: Ingrédient | B20: Qté / portion | C20: Unité | D20: kcal/100 | E20: Prot/100 | F20: Gluc/100 | G20: Lip/100 | H20: kcal | I20: Protéines g | J20: Glucides g | K20: Lipides g | L20: Contrôle
A21: Gnocchis (frais, à poêler ou à pocher) | B21: 250 | C21: g | D21: 150 | E21: 4 | F21: 31 | G21: 1.5 | H21: =B21*D21/100 -> 375 | I21: =B21*E21/100 -> 10 | J21: =B21*F21/100 -> 77.5 | K21: =B21*G21/100 -> 3.75
A22: Oignon | B22: 50 | C22: g | D22: 40 | E22: 1 | F22: 8 | G22: 0 | H22: =B22*D22/100 -> 20 | I22: =B22*E22/100 -> 0.5 | J22: =B22*F22/100 -> 4 | K22: =B22*G22/100 -> 0
A23: Lardons fumés | B23: 60 | C23: g | D23: 300 | E23: 15 | F23: 1 | G23: 27 | H23: =B23*D23/100 -> 180 | I23: =B23*E23/100 -> 9 | J23: =B23*F23/100 -> 0.6 | K23: =B23*G23/100 -> 16.2
A24: Parmesan râpé (ou emmental) | B24: 20 | C24: g | D24: 380 | E24: 28 | F24: 0.5 | G24: 30 | H24: =B24*D24/100 -> 76 | I24: =B24*E24/100 -> 5.6 | J24: =B24*F24/100 -> 0.1 | K24: =B24*G24/100 -> 6
A25: Crème liquide | B25: 100 | C25: ml | D25: 165 | E25: 2.5 | F25: 4 | G25: 15 | H25: =B25*D25/100 -> 165 | I25: =B25*E25/100 -> 2.5 | J25: =B25*F25/100 -> 4 | K25: =B25*G25/100 -> 15
A26: Pousses d'épinards | B26: 50 | C26: g | D26: 20 | E26: 2.5 | F26: 1 | G26: 0.4 | H26: =B26*D26/100 -> 10 | I26: =B26*E26/100 -> 1.25 | J26: =B26*F26/100 -> 0.5 | K26: =B26*G26/100 -> 0.2
A27: Sel | B27: 1 | C27: g | D27: 0 | E27: 0 | F27: 0 | G27: 0 | H27: =B27*D27/100 -> 0 | I27: =B27*E27/100 -> 0 | J27: =B27*F27/100 -> 0 | K27: =B27*G27/100 -> 0
A28: Poivre | B28: 0.5 | C28: g | D28: 0 | E28: 0 | F28: 0 | G28: 0 | H28: =B28*D28/100 -> 0 | I28: =B28*E28/100 -> 0 | J28: =B28*F28/100 -> 0 | K28: =B28*G28/100 -> 0
A29: TOTAL 1 PORTION | H29: =SUM(H21:H28) -> 826 | I29: =SUM(I21:I28) -> 28.85 | J29: =SUM(J21:J28) -> 86.7 | K29: =SUM(K21:K28) -> 41.15 | L29: =IF(H29>=700,"≥ 700 kcal OK","< 700 kcal") -> ≥ 700 kcal OK
A30: x2 (dîner + midi lendemain) | H30: =H29*2 -> 1652 | I30: =I29*2 -> 57.7 | J30: =J29*2 -> 173.4 | K30: =K29*2 -> 82.3
A31: % de l'énergie (P / G / L) | I31: =I29*4/H29 -> 0.13970944 | J31: =J29*4/H29 -> 0.41985472 | K31: =K29*9/H29 -> 0.44836562
A33: 3. Croque-monsieur express
A34: Ingrédient | B34: Qté / portion | C34: Unité | D34: kcal/100 | E34: Prot/100 | F34: Gluc/100 | G34: Lip/100 | H34: kcal | I34: Protéines g | J34: Glucides g | K34: Lipides g | L34: Contrôle
A35: Pain de mie (tranches carrées) | B35: 160 | C35: g | D35: 250 | E35: 9 | F35: 42 | G35: 4 | H35: =B35*D35/100 -> 400 | I35: =B35*E35/100 -> 14.4 | J35: =B35*F35/100 -> 67.2 | K35: =B35*G35/100 -> 6.4
A36: Crème fraîche épaisse | B36: 60 | C36: g | D36: 165 | E36: 2.5 | F36: 4 | G36: 15 | H36: =B36*D36/100 -> 99 | I36: =B36*E36/100 -> 1.5 | J36: =B36*F36/100 -> 2.4 | K36: =B36*G36/100 -> 9
A37: Gruyère / emmental râpé | B37: 50 | C37: g | D37: 380 | E37: 28 | F37: 0.5 | G37: 30 | H37: =B37*D37/100 -> 190 | I37: =B37*E37/100 -> 14 | J37: =B37*F37/100 -> 0.25 | K37: =B37*G37/100 -> 15
A38: Jambon blanc | B38: 70 | C38: g | D38: 110 | E38: 20 | F38: 1 | G38: 3 | H38: =B38*D38/100 -> 77 | I38: =B38*E38/100 -> 14 | J38: =B38*F38/100 -> 0.7 | K38: =B38*G38/100 -> 2.1
A39: Sel | B39: 0.5 | C39: g | D39: 0 | E39: 0 | F39: 0 | G39: 0 | H39: =B39*D39/100 -> 0 | I39: =B39*E39/100 -> 0 | J39: =B39*F39/100 -> 0 | K39: =B39*G39/100 -> 0
A40: Poivre | B40: 0.5 | C40: g | D40: 0 | E40: 0 | F40: 0 | G40: 0 | H40: =B40*D40/100 -> 0 | I40: =B40*E40/100 -> 0 | J40: =B40*F40/100 -> 0 | K40: =B40*G40/100 -> 0
A41: TOTAL 1 PORTION | H41: =SUM(H35:H40) -> 766 | I41: =SUM(I35:I40) -> 43.9 | J41: =SUM(J35:J40) -> 70.55 | K41: =SUM(K35:K40) -> 32.5 | L41: =IF(H41>=700,"≥ 700 kcal OK","< 700 kcal") -> ≥ 700 kcal OK
A42: x2 (dîner + midi lendemain) | H42: =H41*2 -> 1532 | I42: =I41*2 -> 87.8 | J42: =J41*2 -> 141.1 | K42: =K41*2 -> 65
A43: % de l'énergie (P / G / L) | I43: =I41*4/H41 -> 0.22924282 | J43: =J41*4/H41 -> 0.36840731 | K43: =K41*9/H41 -> 0.38185379
...

Sheet Recettes v3 (1 pers)
A1: Fiches 1 personne (x2 pour dîner + midi) — substitutions éco appliquées
A3: # recette | B3: Recette | C3: Ingrédient | D3: Qté / portion | E3: Unité | F3: Équivalent | G3: Produit Chronodrive | H3: Origine | I3: Note de substitution
A4: 1 | B4: Poulet au curry, lait de coco et noix de cajou + riz | C4: Filet de poulet | D4: 130 | E4: g | F4: 1 filet | G4: Filets de poulet | H4: recette
A5: 1 | B5: Poulet au curry, lait de coco et noix de cajou + riz | C5: Lait de coco | D5: 100 | E5: ml | F5: ½ brique de 20 cl | G5: Lait de coco | H5: recette
A6: 1 | B6: Poulet au curry, lait de coco et noix de cajou + riz | C6: Curry en poudre | D6: 2 | E6: g | F6: 1 cc rase | G6: Curry en poudre Ducros 47 g | H6: placard
A7: 1 | B7: Poulet au curry, lait de coco et noix de cajou + riz | C7: Sauce soja | D7: 5 | E7: ml | F7: 1 cc | G7: Sauce soja | H7: recette
A8: 1 | B8: Poulet au curry, lait de coco et noix de cajou + riz | C8: Noix de cajou grillées salées | D8: 20 | E8: g | F8: 1 petite poignée | G8: Noix de cajou | H8: recette
A9: 1 | B9: Poulet au curry, lait de coco et noix de cajou + riz | C9: Maïzena | D9: 5 | E9: g | F9: 1 cc bombée | G9: Farine T45 | H9: placard
A10: 1 | B10: Poulet au curry, lait de coco et noix de cajou + riz | C10: Huile | D10: 15 | E10: ml | F10: 1 cs | G10: Huile de tournesol | H10: placard
A11: 1 | B11: Poulet au curry, lait de coco et noix de cajou + riz | C11: Riz long cru | D11: 80 | E11: g | F11: ½ verre | G11: Riz long | H11: ajout
A12: 1 | B12: Poulet au curry, lait de coco et noix de cajou + riz | C12: Sel | D12: 1 | E12: g | F12: 1 pincée | G12: Sel / poivre | H12: placard
A13: 1 | B13: Poulet au curry, lait de coco et noix de cajou + riz | C13: Poivre | D13: 0.5 | E13: g | F13: 1 tour de moulin | G13: Sel / poivre | H13: placard
A14: 2 | B14: Gnocchis aux épinards, crème et lardons | C14: Gnocchis (frais, à poêler ou à pocher) | D14: 250 | E14: g | F14: ½ paquet de 500 g | G14: Gnocchis à poêler | H14: recette
A15: 2 | B15: Gnocchis aux épinards, crème et lardons | C15: Oignon | D15: 50 | E15: g | F15: ½ oignon moyen | G15: Oignons jaunes | H15: recette
... A20: 2 | B20: Gnocchis aux épinards, crème et lardons | C20: Sel | D20: 1 | E20: g | F20: 1 pincée | G20: Sel / poivre | H20: placard
A21: 2 | B21: Gnocchis aux épinards, crème et lardons | C21: Poivre | D21: 0.5 | E21: g | G21: Sel / poivre | H21: placard
A22: 3 | B22: Croque-monsieur express | C22: Pain de mie (tranches carrées) | D22: 160 | E22: g | F22: 4 tranches (≈ 40 g/tranche) = 2 croques | G22: Pain de mie | H22: recette
A23: 3 | B23: Croque-monsieur express | C23: Crème fraîche épaisse | D23: 60 | E23: g | F23: 3 cs | G23: Crème fraîche épaisse 15 % | H23: recette
A24: 3 | B24: Croque-monsieur express | C24: Gruyère / emmental râpé | D24: 50 | E24: g | F24: 1 grosse poignée | G24: Emmental râpé | H24: recette
A25: 3 | B25: Croque-monsieur express | C25: Jambon blanc | D25: 70 | E25: g | F25: 2 tranches | G25: Jambon blanc | H25: recette
A26: 3 | B26: Croque-monsieur express | C26: Sel | D26: 0.5 | E26: g | F26: 1 pincée | G26: Sel / poivre | H26: placard
A27: 3 | B27: Croque-monsieur express | C27: Poivre | D27: 0.5 | E27: g | G27: Sel / poivre | H27: placard
A28: 4 | B28: Hachis parmentier rapide (purée en flocons) | C28: Steak haché / viande hachée de bœuf | D28: 150 | E28: g | F28: 1 steak + un peu (ou 1 gros) | G28: Haché bovin 15 % | H28: recette | I28: Lait → eau + crème pour la purée.
A29: 4 | B29: Hachis parmentier rapide (purée en flocons) | C29: Oignon | D29: 70 | E29: g | F29: ⅔ d'oignon moyen | G29: Oignons jaunes | H29: recette | I29: Lait → eau + crème pour la purée.
A30: 4 | B30: Hachis parmentier rapide (purée en flocons) | C30: Tomate | D30: 40 | E30: g | F30: ⅓ de tomate | G30: Pulpe de tomate | H30: recette | I30: Lait → eau + crème pour la purée.
A31: 4 | B31: Hachis parmentier rapide (purée en flocons) | C31: Huile d'olive | D31: 10 | E31: ml | F31: 2 cc | G31: Huile de tournesol | H31: recette | I31: Lait → eau + crème pour la purée.
A32: 4 | B32: Hachis parmentier rapide (purée en flocons) | C32: Purée en flocons (sèche) | D32: 60 | E32: g | F32: ½ sachet de 125 g | G32: Purée en flocons | H32: recette | I32: Lait → eau + crème pour la purée.
A33: 4 | B33: Hachis parmentier rapide (purée en flocons) | C33: Lait | D33: 100 | E33: ml | F33: ½ verre | G33: Eau | H33: recette | I33: Lait → eau + crème pour la purée.
A34: 4 | B34: Hachis parmentier rapide (purée en flocons) | C34: Eau | D34: 200 | E34: ml | F34: 1 verre | G34: Eau | H34: recette | I34: Lait → eau + crème pour la purée.
A35: 4 | B35: Hachis parmentier rapide (purée en flocons) | C35: Fromage râpé | D35: 25 | E35: g | F35: 2 cs | G35: Emmental râpé | H35: recette | I35: Lait → eau + crème pour la purée.
A36: 4 | B36: Hachis parmentier rapide (purée en flocons) | C36: Persillade (ail + persil séchés) | D36: 2 | E36: g | F36: 1 cc | G36: Persillade Ducros ≈ 20 g | H36: placard | I36: Lait → eau + crème pour la purée.
A37: 4 | B37: Hachis parmentier rapide (purée en flocons) | C37: Sel | D37: 1 | E37: g | G37: Sel / poivre | H37: placard | I37: Lait → eau + crème pour la purée.
A38: 4 | B38: Hachis parmentier rapide (purée en flocons) | C38: Poivre | D38: 0.5 | E38: g | G38: Sel / poivre | H38: placard | I38: Lait → eau + crème pour la purée.
A39: 5 | B39: Pâtes à la « carbonara » à la française | C39: Pâtes sèches (spaghetti, penne…) | D39: 125 | E39: g | F39: 1 grosse poignée | G39: Spaghetti / pâtes courtes | H39: recette
A40: 5 | B40: Pâtes à la « carbonara » à la française | C40: Crème fraîche (liquide ou épaisse) | D40: 125 | E40: ml | F40: ⅔ de brique de 20 cl | G40: Crème liquide UHT | H40: recette
A41: 5 | B41: Pâtes à la « carbonara » à la française | C41: Jaune d'œuf | D41: 18 | E41: g | F41: 1 jaune (¾ dans la source) | G41: Œufs | H41: recette
A42: 5 | B42: Pâtes à la « carbonara » à la française | C42: Lardons fumés | D42: 60 | E42: g | F42: ½ sachet de 100 g + un peu | G42: Lardons fumés | H42: recette
A43: 5 | B43: Pâtes à la « carbonara » à la française | C43: Oignon | D43: 50 | E43: g | F43: ½ oignon | G43: Oignons jaunes | H43: recette
A44: 5 | B44: Pâtes à la « carbonara » à la française | C44: Sel | D44: 1 | E44: g | F44: 1 pincée | G44: Sel / poivre | H44: placard
A45: 5 | B45: Pâtes à la « carbonara » à la française | C45: Poivre | D45: 1 | E45: g | F45: généreux | G45: Sel / poivre | H45: placard
...

Sheet S1
A1: Semaine 1 — total 47.66 € (marge 7.34 €) — retrait Chronodrive le dimanche
A3: PLANNING
A4: Jour | B4: Midi | C4: Soir | D4: kcal / portion (soir) | E4: À cuisiner ce jour | F4: Note | G4: Macros / portion (P / G / L en g)
A5: Dimanche (retrait) | B5: libre / reste | C5: Pizza : Auchan Pizza royale jambon-fromage-olives 400 g | D5: ≈ 900 | E5: Four 12 min | F5: Retrait du drive le matin
A6: Lundi | B6: Portion 2 de la pizza / reste | C6: 10. Côtes d'échine à la moutarde et à la crème + spaghetti | D6: =ROUND(Nutrition!H148,0) -> 864 | E6: 30 min (5 + 25) — 2 portions | F6: Filet mignon (18,30 €/kg) → côtes d'échine sans os (11,63 €/kg), même sauce moutarde-crème ; tagliatelles → spaghetti. | G6: =ROUND(Nutrition!I148,0)&" / "&ROUND(Nutrition!J148,0)&" / "&ROUND(Nutrition!K148,0) -> 39 / 75 / 44
A7: Mardi | B7: Portion 2 de : Côtes d'échine à la moutarde et à la crème + spaghetti | C7: 16. « Couscous » étudiant poulet, carottes, pois chiches | D7: =ROUND(Nutrition!H253,0) -> 838 | E7: 30 min (annoncé) — mijotage 20-25 min — 2 portions | F7: Semoule montée à 100 g pour passer 700 kcal ; ras el hanout du placard. | G7: =ROUND(Nutrition!I253,0)&" / "&ROUND(Nutrition!J253,0)&" / "&ROUND(Nutrition!K253,0) -> 50 / 105 / 23
A8: Mercredi | B8: Portion 2 de : « Couscous » étudiant poulet, carottes, pois chiches | C8: 5. Pâtes à la « carbonara » à la française | D8: =ROUND(Nutrition!H71,0) -> 876 | E8: 20 min (5 + 15) — 2 portions | G8: =ROUND(Nutrition!I71,0)&" / "&ROUND(Nutrition!J71,0)&" / "&ROUND(Nutrition!K71,0) -> 30 / 100 / 39
A9: Jeudi | B9: Portion 2 de : Pâtes à la « carbonara » à la française | C9: 9. Riz au chorizo et poivrons (façon paella express) | D9: =ROUND(Nutrition!H135,0) -> 708 | E9: 30 min (10 + 20) — 2 portions | F9: Olives supprimées (facultatives, 2 € le bocal). | G9: =ROUND(Nutrition!I135,0)&" / "&ROUND(Nutrition!J135,0)&" / "&ROUND(Nutrition!K135,0) -> 21 / 77 / 35
A10: Vendredi | B10: Portion 2 de : Riz au chorizo et poivrons (façon paella express) | C10: 15. Saucisses-lentilles express (lentilles en conserve) | D10: =ROUND(Nutrition!H235,0) -> 780 | E10: 15 min — 2 portions | G10: =ROUND(Nutrition!I235,0)&" / "&ROUND(Nutrition!J235,0)&" / "&ROUND(Nutrition!K235,0) -> 38 / 36 / 52
A11: Samedi | B11: Portion 2 de : Saucisses-lentilles express (lentilles en conserve) | C11: ½ Auchan Poulet basquaise et riz 900 g | D11: ≈ 900-1 000 | E11: Poêle / micro-ondes | F11: Sachet coupé en 2 (congélateur)
A12: Dimanche midi | B12: ½ Auchan Poulet basquaise et riz 900 g | C12: → pizza de la semaine suivante
A14: LISTE DE COURSES CHRONODRIVE — formats entiers
A15: Produit exact (Chronodrive) | B15: Rayon | C15: Qté à acheter | D15: Prix unitaire € | E15: Total € | F15: Besoin semaine (2 portions x 5) | G15: Acheté | H15: Unité | I15: Reste après la semaine | J15: dont gâchis estimé € | K15: dont stock (se garde) € | L15: Sert aux recettes
A16: Auchan chorizo doux 24 tranches 120 g | B16: Charcuterie | C16: 1 | D16: 1.85 | E16: =C16*D16 -> 1.85 | F16: 120 | G16: 120 | H16: g | I16: 0 | J16: 0 | K16: 0 | L16: 9
A17: Auchan lardons fumés 2 x 100 g | B17: Charcuterie | C17: 1 | D17: 2.09 | E17: =C17*D17 -> 2.09 | F17: 200 | G17: 200 | H17: g | I17: 0 | J17: 0 | K17: 0 | L17: 5, 15
A18: Auchan Knacks 10 pièces 350 g | B18: Charcuterie | C18: 1 | D18: 1.75 | E18: =C18*D18 -> 1.75 | F18: 280 | G18: 350 | H18: g | I18: 70 | J18: 0.175 | K18: 0.175 | L18: 15
A19: Auchan crème épaisse légère 15 % 20 cl | B19: Crèmerie | C19: 1 | D19: 0.75 | E19: =C19*D19 -> 0.75 | F19: 80 | G19: 200 | H19: ml | I19: 120 | J19: 0.135 | K19: 0.315 | L19: 10
A20: Auchan Essentiel crème fluide légère 15 % 20 cl | B20: Crèmerie | C20: 2 | D20: 0.69 | E20: =C20*D20 -> 1.38 | F20: 250 | G20: 400 | H20: ml | I20: 150 | J20: 0 | K20: 0.5175 | L20: 5
A21: Auchan œufs plein air x6 | B21: Crèmerie | C21: 1 | D21: 1.69 | E21: =C21*D21 -> 1.69 | F21: 36 | G21: 330 | H21: g | I21: 294 | J21: 0 | K21: 1.5056364 | L21: 5
A22: Carottes zéro résidu 750 g | B22: Fruits & légumes | C22: 1 | D22: 2.29 | E22: =C22*D22 -> 2.29 | F22: 300 | G22: 750 | H22: g | I22: 450 | J22: 0.687 | K22: 0.687 | L22: 15, 16
A23: Oignon jaune 1 kg | B23: Fruits & légumes | C23: 1 | D23: 2.69 | E23: =C23*D23 -> 2.69 | F23: 320 | G23: 1000 | H23: g | I23: 680 | J23: 0.36584 | K23: 1.46336 | L23: 5, 9, 15, 16
A24: Poivron rouge 1 pièce | B24: Fruits & légumes | C24: 1 | D24: 0.99 | E24: =C24*D24 -> 0.99 | F24: 100 | G24: 150 | H24: g | I24: 50 | J24: 0.33 | K24: 0 | L24: 9
A25: Porc côtes échines sans os LR 2 pièces 300 g | B25: Viande | C25: 1 | D25: 3.49 | E25: =C25*D25 -> 3.49 | F25: 300 | G25: 300 | H25: g | I25: 0 | J25: 0 | K25: 0 | L25: 10
A26: Auchan filets de poulet blanc 260 g | B26: Viande | C26: 1 | D26: 3.89 | E26: =C26*D26 -> 3.89 | F26: 240 | G26: 260 | H26: g | I26: 20 | J26: 0.29923077 | K26: 0 | L26: 16
A27: Auchan lentilles préparées 530 g | B27: Épicerie | C27: 1 | D27: 1.29 | E27: =C27*D27 -> 1.29 | F27: 400 | G27: 530 | H27: g | I27: 130 | J27: 0.094924528 | K27: 0.22149057 | L27: 15
... A31: Auchan spaghetti 500 g | B31: Épicerie | C31: 1 | D31: 0.75 | E31: =C31*D31 -> 0.75 | F31: 450 | G31: 500 | H31: g | I31: 50 | J31: 0 | K31: 0.075 | L31: 5, 10
A32: TOTAL COURSES RECETTES | E32: =SUM(E16:E31) -> 28.03 | J32: =SUM(J16:J31) -> 2.1451274 | K32: =SUM(K16:K31) -> 6.7834284
A33: Auchan Poulet basquaise et riz 900 g | B33: Surgelé (week-end) | C33: 1 | D33: 4.75 | E33: =C33*D33 -> 4.75 | L33: Samedi soir + dimanche midi
A34: Auchan Pizza royale jambon-fromage-olives 400 g | B34: Surgelé (week-end) | C34: 1 | D34: 2.15 | E34: =C34*D34 -> 2.15 | L34: Dimanche soir
A35: TOTAL PANIER (recettes + week-end) | E35: =E32+E33+E34 -> 34.93
A37: PLACARD / BASES utilisées cette semaine — comptées au PRIX PLEIN du format
A38: Produit exact | B38: Rayon | C38: Qté | D38: Prix format € | E38: Total € | F38: Qté utilisée cette semaine | G38: Contenu format | H38: Unité | I38: Reste (stock) | K38: Valeur du reste € | L38: Sert aux recettes
A39: Beurre | B39: Placard | C39: 1 | D39: 2.45 | E39: =C39*D39 -> 2.45 | F39: 30 | G39: 250 | H39: g | I39: 220 | K39: =D39*I39/G39 -> 2.156 | L39: 10, 15
A40: Bouillon cube | B40: Placard | C40: 1 | D40: 1.79 | E40: =C40*D40 -> 1.79 | F40: 16 | G40: 180 | H40: g | I40: 164 | K40: =D40*I40/G40 -> 1.6308889 | L40: 9, 16
A41: Huile de tournesol | B41: Placard | C41: 1 | D41: 2.15 | E41: =C41*D41 -> 2.15 | F41: 50 | G41: 1000 | H41: ml | I41: 950 | K41: =D41*I41/G41 -> 2.0425 | L41: 9, 16
A42: Moutarde de Dijon | B42: Placard | C42: 1 | D42: 1.85 | E42: =C42*D42 -> 1.85 | F42: 30 | G42: 430 | H42: g | I42: 400 | K42: =D42*I42/G42 -> 1.7209302 | L42: 10
A43: Ras el hanout La Conquête des Saveurs 240 g | B43: Placard | C43: 1 | D43: 3.99 | E43: =C43*D43 -> 3.99 | F43: 14 | G43: 240 | H43: g | I43: 226 | K43: =D43*I43/G43 -> 3.75725 | L43: 16
A44: Sel / poivre | B44: Placard | C44: 1 | D44: 0.5 | E44: =C44*D44 -> 0.5 | F44: 12 | G44: 100 | H44: g | I44: 88 | K44: =D44*I44/G44 -> 0.44 | L44: 5, 9, 10, 15, 16
A45: TOTAL placard (prix plein) | E45: =SUM(E39:E44) -> 12.73
A47: BUDGET
...

Sheet S2
A1: Semaine 2 — total 45.09 € (marge 9.91 €) — retrait Chronodrive le dimanche
A3: PLANNING
A4: Jour | B4: Midi | C4: Soir | D4: kcal / portion (soir) | E4: À cuisiner ce jour | F4: Note | G4: Macros / portion (P / G / L en g)
A5: Dimanche (retrait) | B5: libre / reste | C5: Pizza : Ristorante 4 fromages 340 g | D5: ≈ 900 | E5: Four 12 min | F5: Retrait du drive le matin
A6: Lundi | B6: Portion 2 de la pizza / reste | C6: 3. Croque-monsieur express | D6: =ROUND(Nutrition!H41,0) -> 766 | E6: 25 min (5 + 20) — 2 portions | G6: =ROUND(Nutrition!I41,0)&" / "&ROUND(Nutrition!J41,0)&" / "&ROUND(Nutrition!K41,0) -> 44 / 71 / 33
A7: Mardi | B7: Portion 2 de : Croque-monsieur express | C7: 2. Gnocchis aux épinards, crème et lardons | D7: =ROUND(Nutrition!H29,0) -> 826 | E7: 12 min (5 + 7) — 2 portions | G7: =ROUND(Nutrition!I29,0)&" / "&ROUND(Nutrition!J29,0)&" / "&ROUND(Nutrition!K29,0) -> 29 / 87 / 41
A8: Mercredi | B8: Portion 2 de : Gnocchis aux épinards, crème et lardons | C8: 22. Frittata d'été aux courgettes et mozzarella filante (+ pain) | D8: =ROUND(Nutrition!H356,0) -> 716 | E8: 20 min — 2 portions | F8: Tomate → tomates cerises 125 g ; pain = ½ mini-baguette précuite x2 (80 g). | G8: =ROUND(Nutrition!I356,0)&" / "&ROUND(Nutrition!J356,0)&" / "&ROUND(Nutrition!K356,0) -> 36 / 45 / 42
A9: Jeudi | B9: Portion 2 de : Frittata d'été aux courgettes et mozzarella filante (+ pain) | C9: 21. Risotto de coquillettes au jambon, petits pois et parmesan | D9: =ROUND(Nutrition!H339,0) -> 738 | E9: 25 min (5 + 20) — 2 portions | F9: Mascarpone → crème épaisse. | G9: =ROUND(Nutrition!I339,0)&" / "&ROUND(Nutrition!J339,0)&" / "&ROUND(Nutrition!K339,0) -> 39 / 103 / 18
A10: Vendredi | B10: Portion 2 de : Risotto de coquillettes au jambon, petits pois et parmesan | C10: 24. Pâtes sauce tomate-basilic, mozzarella fondante & parmesan | D10: =ROUND(Nutrition!H382,0) -> 807 | E10: 15 min (3 + 12) — 2 portions | F10: Sans oignon ni tomates cerises (ton choix) ; sauce du commerce mijotée 5 min ; 1 boule de mozzarella pour 2 portions ; parmesan ajouté. | G10: =ROUND(Nutrition!I382,0)&" / "&ROUND(Nutrition!J382,0)&" / "&ROUND(Nutrition!K382,0) -> 34 / 105 / 26
A11: Samedi | B11: Portion 2 de : Pâtes sauce tomate-basilic, mozzarella fondante & parmesan | C11: ½ Auchan Penne poulet-champignons 900 g | D11: ≈ 900-1 000 | E11: Poêle / micro-ondes | F11: Sachet coupé en 2 (congélateur)
A12: Dimanche midi | B12: ½ Auchan Penne poulet-champignons 900 g | C12: → pizza de la semaine suivante
A14: LISTE DE COURSES CHRONODRIVE — formats entiers
A15: Produit exact (Chronodrive) | B15: Rayon | C15: Qté à acheter | D15: Prix unitaire € | E15: Total € | F15: Besoin semaine (2 portions x 5) | G15: Acheté | H15: Unité | I15: Reste après la semaine | J15: dont gâchis estimé € | K15: dont stock (se garde) € | L15: Sert aux recettes
A16: Auchan Jambon de Paris 8 tranches 280 g | B16: Charcuterie | C16: 1 | D16: 3.25 | E16: =C16*D16 -> 3.25 | F16: 280 | G16: 280 | H16: g | I16: 0 | J16: 0 | K16: 0 | L16: 3, 21
A17: Auchan lardons fumés 2 x 100 g | B17: Charcuterie | C17: 1 | D17: 2.09 | E17: =C17*D17 -> 2.09 | F17: 120 | G17: 200 | H17: g | I17: 80 | J17: 0.418 | K17: 0.418 | L17: 2
A18: Auchan crème épaisse légère 15 % 20 cl | B18: Crèmerie | C18: 1 | D18: 0.75 | E18: =C18*D18 -> 0.75 | F18: 170 | G18: 200 | H18: ml | I18: 30 | J18: 0.03375 | K18: 0.07875 | L18: 3, 21
A19: Auchan Essentiel crème fluide légère 15 % 20 cl | B19: Crèmerie | C19: 1 | D19: 0.69 | E19: =C19*D19 -> 0.69 | F19: 200 | G19: 200 | H19: ml | I19: 0 | J19: 0 | K19: 0 | L19: 2
A20: Auchan emmental râpé 3 x 70 g | B20: Crèmerie | C20: 1 | D20: 2.09 | E20: =C20*D20 -> 2.09 | F20: 140 | G20: 210 | H20: g | I20: 70 | J20: 0.13933333 | K20: 0.55733333 | L20: 2, 3
A21: Auchan Tavola grana padano râpé 60 g | B21: Crèmerie | C21: 1 | D21: 1.19 | E21: =C21*D21 -> 1.19 | F21: 60 | G21: 60 | H21: g | I21: 0 | J21: 0 | K21: 0 | L21: 21, 24
A22: Casa Azzurra mozzarella 125 g | B22: Crèmerie | C22: 2 | D22: 1.15 | E22: =C22*D22 -> 2.3 | F22: 248 | G22: 250 | H22: g | I22: 2 | J22: 0.0184 | K22: 0 | L22: 22, 24
A23: Auchan œufs plein air x6 | B23: Crèmerie | C23: 1 | D23: 1.69 | E23: =C23*D23 -> 1.69 | F23: 220 | G23: 330 | H23: g | I23: 110 | J23: 0 | K23: 0.56333333 | L23: 22
A24: Auchan gnocchi de pomme de terre à poêler 500 g | B24: Frais | C24: 1 | D24: 1.85 | E24: =C24*D24 -> 1.85 | F24: 500 | G24: 500 | H24: g | I24: 0 | J24: 0 | K24: 0 | L24: 2
A25: Citron jaune 1 pièce | B25: Fruits & légumes | C25: 1 | D25: 0.85 | E25: =C25*D25 -> 0.85 | F25: 50 | G25: 100 | H25: g | I25: 50 | J25: 0.2125 | K25: 0.2125 | L25: 22
A26: Courgette 1 pièce | B26: Fruits & légumes | C26: 2 | D26: 0.99 | E26: =C26*D26 -> 1.98 | F26: 350 | G26: 500 | H26: g | I26: 150 | J26: 0.594 | K26: 0 | L26: 22
A27: Oignon jaune 1 kg | B27: Fruits & légumes | C27: 1 | D27: 2.69 | E27: =C27*D27 -> 2.69 | F27: 200 | G27: 1000 | H27: g | I27: 800 | J27: 0.4304 | K27: 1.7216 | L27: 2, 21
... A34: Auchan spaghetti 500 g | B34: Épicerie | C34: 1 | D34: 0.75 | E34: =C34*D34 -> 0.75 | F34: 250 | G34: 500 | H34: g | I34: 250 | J34: 0 | K34: 0.375 | L34: 24
A35: TOTAL COURSES RECETTES | E35: =SUM(E16:E34) -> 29.93 | J35: =SUM(J16:J34) -> 2.2685738 | K35: =SUM(K16:K34) -> 5.1177186
A36: Auchan Penne poulet-champignons 900 g | B36: Surgelé (week-end) | C36: 1 | D36: 4.65 | E36: =C36*D36 -> 4.65 | L36: Samedi soir + dimanche midi
A37: Ristorante 4 fromages 340 g | B37: Surgelé (week-end) | C37: 1 | D37: 2.89 | E37: =C37*D37 -> 2.89 | L37: Dimanche soir
A38: TOTAL PANIER (recettes + week-end) | E38: =E35+E36+E37 -> 37.47
A40: PLACARD / BASES utilisées cette semaine — comptées au PRIX PLEIN du format
A41: Produit exact | B41: Rayon | C41: Qté | D41: Prix format € | E41: Total € | F41: Qté utilisée cette semaine | G41: Contenu format | H41: Unité | I41: Reste (stock) | K41: Valeur du reste € | L41: Sert aux recettes
A42: Ail semoule | B42: Placard | C42: 1 | D42: 1.29 | E42: =C42*D42 -> 1.29 | F42: 12 | G42: 55 | H42: g | I42: 43 | K42: =D42*I42/G42 -> 1.0085455 | L42: 21, 22
A43: Bouillon cube | B43: Placard | C43: 1 | D43: 1.79 | E43: =C43*D43 -> 1.79 | F43: 10 | G43: 180 | H43: g | I43: 170 | K43: =D43*I43/G43 -> 1.6905556 | L43: 21
A44: Huile de tournesol | B44: Placard | C44: 1 | D44: 2.15 | E44: =C44*D44 -> 2.15 | F44: 50 | G44: 1000 | H44: ml | I44: 950 | K44: =D44*I44/G44 -> 2.0425 | L44: 21, 22, 24
A45: Origan Ducros 12 g | B45: Placard | C45: 1 | D45: 1.89 | E45: =C45*D45 -> 1.89 | F45: 1 | G45: 12 | H45: g | I45: 11 | K45: =D45*I45/G45 -> 1.7325 | L45: 22
A46: Sel / poivre | B46: Placard | C46: 1 | D46: 0.5 | E46: =C46*D46 -> 0.5 | F46: 11 | G46: 100 | H46: g | I46: 89 | K46: =D46*I46/G46 -> 0.445 | L46: 2, 3, 21, 22, 24
A47: TOTAL placard (prix plein) | E47: =SUM(E42:E46) -> 7.62
A49: BUDGET
A50: Panier recettes + week-end | E50: =E38 -> 37.47
...

Sheet S3
A1: Semaine 3 — total 55.13 € (marge -0.13 €) — retrait Chronodrive le dimanche
A3: PLANNING
A4: Jour | B4: Midi | C4: Soir | D4: kcal / portion (soir) | E4: À cuisiner ce jour | F4: Note | G4: Macros / portion (P / G / L en g)
A5: Dimanche (retrait) | B5: libre / reste | C5: Pizza : Auchan Pizza au chèvre 390 g | D5: ≈ 900 | E5: Four 12 min | F5: Retrait du drive le matin
A6: Lundi | B6: Portion 2 de la pizza / reste | C6: 10. Côtes d'échine à la moutarde et à la crème + spaghetti | D6: =ROUND(Nutrition!H148,0) -> 864 | E6: 30 min (5 + 25) — 2 portions | F6: Filet mignon (18,30 €/kg) → côtes d'échine sans os (11,63 €/kg), même sauce moutarde-crème ; tagliatelles → spaghetti. | G6: =ROUND(Nutrition!I148,0)&" / "&ROUND(Nutrition!J148,0)&" / "&ROUND(Nutrition!K148,0) -> 39 / 75 / 44
A7: Mardi | B7: Portion 2 de : Côtes d'échine à la moutarde et à la crème + spaghetti | C7: 12. Ravioli poêlés à la tomate et mozzarella | D7: =ROUND(Nutrition!H186,0) -> 908 | E7: 15 min — 2 portions | F7: Ravioles du Dauphiné (13,54 €/kg) → ravioli Auchan aux fromages (5,63 €/kg), même geste poêlé ; coulis → pulpe. | G7: =ROUND(Nutrition!I186,0)&" / "&ROUND(Nutrition!J186,0)&" / "&ROUND(Nutrition!K186,0) -> 41 / 94 / 40
A8: Mercredi | B8: Portion 2 de : Ravioli poêlés à la tomate et mozzarella | C8: 23. Pâtes pesto caprese (boule de mozzarella, tomates cerises) | D8: =ROUND(Nutrition!H369,0) -> 1050 | E8: 15 min (5 + 10) — 2 portions | F8: Version sans cuisson à part les pâtes ; 1 boule de mozzarella entière par portion (ton choix) ; lardons de la source supprimés. | G8: =ROUND(Nutrition!I369,0)&" / "&ROUND(Nutrition!J369,0)&" / "&ROUND(Nutrition!K369,0) -> 46 / 99 / 50
A9: Jeudi | B9: Portion 2 de : Pâtes pesto caprese (boule de mozzarella, tomates cerises) | C9: 1. Poulet au curry, lait de coco et noix de cajou + riz | D9: =ROUND(Nutrition!H15,0) -> 885 | E9: 25 min (10 + 15) — 2 portions | G9: =ROUND(Nutrition!I15,0)&" / "&ROUND(Nutrition!J15,0)&" / "&ROUND(Nutrition!K15,0) -> 42 / 75 / 46
A10: Vendredi | B10: Portion 2 de : Poulet au curry, lait de coco et noix de cajou + riz | C10: 7. Quesadillas chorizo-emmental & avocat (version éco) | D10: =ROUND(Nutrition!H105,0) -> 959 | E10: 20 min — 2 portions | F10: Version éco : cheddar + gouda → 60 g d'emmental ; ½ avocat (75 g) ; cuisson poêle. | G10: =ROUND(Nutrition!I105,0)&" / "&ROUND(Nutrition!J105,0)&" / "&ROUND(Nutrition!K105,0) -> 37 / 45 / 69
A11: Samedi | B11: Portion 2 de : Quesadillas chorizo-emmental & avocat (version éco) | C11: ½ Marie Lasagnes à la bolognaise 1 kg | D11: ≈ 900-1 000 | E11: Poêle / micro-ondes | F11: Sachet coupé en 2 (congélateur)
A12: Dimanche midi | B12: ½ Marie Lasagnes à la bolognaise 1 kg | C12: → pizza de la semaine suivante
A14: LISTE DE COURSES CHRONODRIVE — formats entiers
A15: Produit exact (Chronodrive) | B15: Rayon | C15: Qté à acheter | D15: Prix unitaire € | E15: Total € | F15: Besoin semaine (2 portions x 5) | G15: Acheté | H15: Unité | I15: Reste après la semaine | J15: dont gâchis estimé € | K15: dont stock (se garde) € | L15: Sert aux recettes
A16: Auchan chorizo doux 24 tranches 120 g | B16: Charcuterie | C16: 1 | D16: 1.85 | E16: =C16*D16 -> 1.85 | F16: 100 | G16: 120 | H16: g | I16: 20 | J16: 0.0925 | K16: 0.21583333 | L16: 7
A17: Auchan crème épaisse légère 15 % 20 cl | B17: Crèmerie | C17: 1 | D17: 0.75 | E17: =C17*D17 -> 0.75 | F17: 180 | G17: 200 | H17: ml | I17: 20 | J17: 0.0225 | K17: 0.0525 | L17: 7, 10
A18: Auchan emmental râpé 3 x 70 g | B18: Crèmerie | C18: 1 | D18: 2.09 | E18: =C18*D18 -> 2.09 | F18: 200 | G18: 210 | H18: g | I18: 10 | J18: 0.019904762 | K18: 0.079619048 | L18: 7, 12
A19: Auchan Tavola grana padano râpé 60 g | B19: Crèmerie | C19: 1 | D19: 1.19 | E19: =C19*D19 -> 1.19 | F19: 30 | G19: 60 | H19: g | I19: 30 | J19: 0 | K19: 0.595 | L19: 23
A20: Casa Azzurra mozzarella 125 g | B20: Crèmerie | C20: 2 | D20: 1.15 | E20: =C20*D20 -> 2.3 | F20: 250 | G20: 250 | H20: g | I20: 0 | J20: 0 | K20: 0 | L20: 23
A21: Auchan ravioli aux fromages 300 g | B21: Frais | C21: 2 | D21: 1.69 | E21: =C21*D21 -> 3.38 | F21: 500 | G21: 600 | H21: g | I21: 100 | J21: 0.56333333 | K21: 0 | L21: 12
A22: Avocat 1 pièce | B22: Fruits & légumes | C22: 1 | D22: 1.59 | E22: =C22*D22 -> 1.59 | F22: 150 | G22: 150 | H22: g | I22: 0 | J22: 0 | K22: 0 | L22: 7
A23: Tomates cerises 250 g | B23: Fruits & légumes | C23: 2 | D23: 0.99 | E23: =C23*D23 -> 1.98 | F23: 370 | G23: 500 | H23: g | I23: 130 | J23: 0.5148 | K23: 0 | L23: 12, 23
A24: Porc côtes échines sans os LR 2 pièces 300 g | B24: Viande | C24: 1 | D24: 3.49 | E24: =C24*D24 -> 3.49 | F24: 300 | G24: 300 | H24: g | I24: 0 | J24: 0 | K24: 0 | L24: 10
A25: Auchan filets de poulet blanc 260 g | B25: Viande | C25: 1 | D25: 3.89 | E25: =C25*D25 -> 3.89 | F25: 260 | G25: 260 | H25: g | I25: 0 | J25: 0 | K25: 0 | L25: 1
A26: Auchan Recette d'Asie lait de coco 20 cl | B26: Épicerie | C26: 1 | D26: 0.95 | E26: =C26*D26 -> 0.95 | F26: 200 | G26: 200 | H26: ml | I26: 0 | J26: 0 | K26: 0 | L26: 1
A27: Auchan Essentiel noix de cajou 125 g | B27: Épicerie | C27: 1 | D27: 1.39 | E27: =C27*D27 -> 1.39 | F27: 40 | G27: 125 | H27: g | I27: 85 | J27: 0 | K27: 0.9452 | L27: 1
... A32: Auchan tortillas de blé 8 pièces 320 g | B32: Épicerie | C32: 1 | D32: 2.05 | E32: =C32*D32 -> 2.05 | F32: 160 | G32: 320 | H32: g | I32: 160 | J32: 0.5125 | K32: 0.5125 | L32: 7
A33: TOTAL COURSES RECETTES | E33: =SUM(E16:E32) -> 32.22 | J33: =SUM(J16:J32) -> 2.4149003 | K33: =SUM(K16:K32) -> 4.5582145
A34: Marie Lasagnes à la bolognaise 1 kg | B34: Surgelé (week-end) | C34: 1 | D34: 5.79 | E34: =C34*D34 -> 5.79 | L34: Samedi soir + dimanche midi
A35: Auchan Pizza au chèvre 390 g | B35: Surgelé (week-end) | C35: 1 | D35: 2.49 | E35: =C35*D35 -> 2.49 | L35: Dimanche soir
A36: TOTAL PANIER (recettes + week-end) | E36: =E33+E34+E35 -> 40.5
A38: PLACARD / BASES utilisées cette semaine — comptées au PRIX PLEIN du format
A39: Produit exact | B39: Rayon | C39: Qté | D39: Prix format € | E39: Total € | F39: Qté utilisée cette semaine | G39: Contenu format | H39: Unité | I39: Reste (stock) | K39: Valeur du reste € | L39: Sert aux recettes
A40: Basilic séché Ducros ≈ 12 g | B40: Placard | C40: 1 | D40: 1.8 | E40: =C40*D40 -> 1.8 | F40: 4 | G40: 12 | H40: g | I40: 8 | K40: =D40*I40/G40 -> 1.2 | L40: 12
A41: Beurre | B41: Placard | C41: 1 | D41: 2.45 | E41: =C41*D41 -> 2.45 | F41: 20 | G41: 250 | H41: g | I41: 230 | K41: =D41*I41/G41 -> 2.254 | L41: 10
A42: Curry en poudre Ducros 47 g | B42: Placard | C42: 1 | D42: 2.15 | E42: =C42*D42 -> 2.15 | F42: 4 | G42: 47 | H42: g | I42: 43 | K42: =D42*I42/G42 -> 1.9670213 | L42: 1
A43: Farine T45 | B43: Placard | C43: 1 | D43: 0.95 | E43: =C43*D43 -> 0.95 | F43: 10 | G43: 1000 | H43: g | I43: 990 | K43: =D43*I43/G43 -> 0.9405 | L43: 1
A44: Huile de tournesol | B44: Placard | C44: 1 | D44: 2.15 | E44: =C44*D44 -> 2.15 | F44: 60 | G44: 1000 | H44: ml | I44: 940 | K44: =D44*I44/G44 -> 2.021 | L44: 1, 7, 12
A45: Moutarde de Dijon | B45: Placard | C45: 1 | D45: 1.85 | E45: =C45*D45 -> 1.85 | F45: 30 | G45: 430 | H45: g | I45: 400 | K45: =D45*I45/G45 -> 1.7209302 | L45: 10
A46: Sauce soja | B46: Placard | C46: 1 | D46: 1.69 | E46: =C46*D46 -> 1.69 | F46: 10 | G46: 150 | H46: ml | I46: 140 | K46: =D46*I46/G46 -> 1.5773333 | L46: 1
A47: Sel / poivre | B47: Placard | C47: 1 | D47: 0.5 | E47: =C47*D47 -> 0.5 | F47: 12 | G47: 100 | H47: g | I47: 88 | K47: =D47*I47/G47 -> 0.44 | L47: 1, 7, 10, 12, 23
...

Sheet S4
A1: Semaine 4 — total 49.05 € (marge 5.95 €) — retrait Chronodrive le dimanche
A3: PLANNING
A4: Jour | B4: Midi | C4: Soir | D4: kcal / portion (soir) | E4: À cuisiner ce jour | F4: Note | G4: Macros / portion (P / G / L en g)
A5: Dimanche (retrait) | B5: libre / reste | C5: Pizza : Auchan Pizza bolognaise 390 g | D5: ≈ 900 | E5: Four 12 min | F5: Retrait du drive le matin
A6: Lundi | B6: Portion 2 de la pizza / reste | C6: 16. « Couscous » étudiant poulet, carottes, pois chiches | D6: =ROUND(Nutrition!H253,0) -> 838 | E6: 30 min (annoncé) — mijotage 20-25 min — 2 portions | F6: Semoule montée à 100 g pour passer 700 kcal ; ras el hanout du placard. | G6: =ROUND(Nutrition!I253,0)&" / "&ROUND(Nutrition!J253,0)&" / "&ROUND(Nutrition!K253,0) -> 50 / 105 / 23
A7: Mardi | B7: Portion 2 de : « Couscous » étudiant poulet, carottes, pois chiches | C7: 24. Pâtes sauce tomate-basilic, mozzarella fondante & parmesan | D7: =ROUND(Nutrition!H382,0) -> 807 | E7: 15 min (3 + 12) — 2 portions | F7: Sans oignon ni tomates cerises (ton choix) ; sauce du commerce mijotée 5 min ; 1 boule de mozzarella pour 2 portions ; parmesan ajouté. | G7: =ROUND(Nutrition!I382,0)&" / "&ROUND(Nutrition!J382,0)&" / "&ROUND(Nutrition!K382,0) -> 34 / 105 / 26
A8: Mercredi | B8: Portion 2 de : Pâtes sauce tomate-basilic, mozzarella fondante & parmesan | C8: 9. Riz au chorizo et poivrons (façon paella express) | D8: =ROUND(Nutrition!H135,0) -> 708 | E8: 30 min (10 + 20) — 2 portions | F8: Olives supprimées (facultatives, 2 € le bocal). | G8: =ROUND(Nutrition!I135,0)&" / "&ROUND(Nutrition!J135,0)&" / "&ROUND(Nutrition!K135,0) -> 21 / 77 / 35
A9: Jeudi | B9: Portion 2 de : Riz au chorizo et poivrons (façon paella express) | C9: 19. Pâtes crémeuses au chèvre, miel et lardons | D9: =ROUND(Nutrition!H304,0) -> 863 | E9: 15 min — 2 portions | G9: =ROUND(Nutrition!I304,0)&" / "&ROUND(Nutrition!J304,0)&" / "&ROUND(Nutrition!K304,0) -> 33 / 96 / 38
A10: Vendredi | B10: Portion 2 de : Pâtes crémeuses au chèvre, miel et lardons | C10: 15. Saucisses-lentilles express (lentilles en conserve) | D10: =ROUND(Nutrition!H235,0) -> 780 | E10: 15 min — 2 portions | G10: =ROUND(Nutrition!I235,0)&" / "&ROUND(Nutrition!J235,0)&" / "&ROUND(Nutrition!K235,0) -> 38 / 36 / 52
A11: Samedi | B11: Portion 2 de : Saucisses-lentilles express (lentilles en conserve) | C11: ½ Auchan Torsades à la carbonara 900 g | D11: ≈ 900-1 000 | E11: Poêle / micro-ondes | F11: Sachet coupé en 2 (congélateur)
A12: Dimanche midi | B12: ½ Auchan Torsades à la carbonara 900 g | C12: → pizza de la semaine suivante
A14: LISTE DE COURSES CHRONODRIVE — formats entiers
A15: Produit exact (Chronodrive) | B15: Rayon | C15: Qté à acheter | D15: Prix unitaire € | E15: Total € | F15: Besoin semaine (2 portions x 5) | G15: Acheté | H15: Unité | I15: Reste après la semaine | J15: dont gâchis estimé € | K15: dont stock (se garde) € | L15: Sert aux recettes
A16: Auchan chorizo doux 24 tranches 120 g | B16: Charcuterie | C16: 1 | D16: 1.85 | E16: =C16*D16 -> 1.85 | F16: 120 | G16: 120 | H16: g | I16: 0 | J16: 0 | K16: 0 | L16: 9
A17: Auchan lardons fumés 2 x 100 g | B17: Charcuterie | C17: 1 | D17: 2.09 | E17: =C17*D17 -> 2.09 | F17: 180 | G17: 200 | H17: g | I17: 20 | J17: 0.1045 | K17: 0.1045 | L17: 15, 19
A18: Auchan Knacks 10 pièces 350 g | B18: Charcuterie | C18: 1 | D18: 1.75 | E18: =C18*D18 -> 1.75 | F18: 280 | G18: 350 | H18: g | I18: 70 | J18: 0.175 | K18: 0.175 | L18: 15
A19: Auchan bûche de chèvre fondant 180 g | B19: Crèmerie | C19: 1 | D19: 2.09 | E19: =C19*D19 -> 2.09 | F19: 100 | G19: 180 | H19: g | I19: 80 | J19: 0.46444444 | K19: 0.46444444 | L19: 19
A20: Auchan Essentiel crème fluide légère 15 % 20 cl | B20: Crèmerie | C20: 1 | D20: 0.69 | E20: =C20*D20 -> 0.69 | F20: 150 | G20: 200 | H20: ml | I20: 50 | J20: 0 | K20: 0.1725 | L20: 19
A21: Auchan Tavola grana padano râpé 60 g | B21: Crèmerie | C21: 1 | D21: 1.19 | E21: =C21*D21 -> 1.19 | F21: 30 | G21: 60 | H21: g | I21: 30 | J21: 0 | K21: 0.595 | L21: 24
A22: Casa Azzurra mozzarella 125 g | B22: Crèmerie | C22: 1 | D22: 1.15 | E22: =C22*D22 -> 1.15 | F22: 124 | G22: 125 | H22: g | I22: 1 | J22: 0.0092 | K22: 0 | L22: 24
A23: Carottes zéro résidu 750 g | B23: Fruits & légumes | C23: 1 | D23: 2.29 | E23: =C23*D23 -> 2.29 | F23: 300 | G23: 750 | H23: g | I23: 450 | J23: 0.687 | K23: 0.687 | L23: 15, 16
A24: Oignon jaune 1 kg | B24: Fruits & légumes | C24: 1 | D24: 2.69 | E24: =C24*D24 -> 2.69 | F24: 250 | G24: 1000 | H24: g | I24: 750 | J24: 0.4035 | K24: 1.614 | L24: 9, 15, 16, 19
A25: Poivron rouge 1 pièce | B25: Fruits & légumes | C25: 1 | D25: 0.99 | E25: =C25*D25 -> 0.99 | F25: 100 | G25: 150 | H25: g | I25: 50 | J25: 0.33 | K25: 0 | L25: 9
A26: Auchan filets de poulet blanc 260 g | B26: Viande | C26: 1 | D26: 3.89 | E26: =C26*D26 -> 3.89 | F26: 240 | G26: 260 | H26: g | I26: 20 | J26: 0.29923077 | K26: 0 | L26: 16
A27: Auchan lentilles préparées 530 g | B27: Épicerie | C27: 1 | D27: 1.29 | E27: =C27*D27 -> 1.29 | F27: 400 | G27: 530 | H27: g | I27: 130 | J27: 0.094924528 | K27: 0.22149057 | L27: 15
... A32: Auchan spaghetti 500 g | B32: Épicerie | C32: 1 | D32: 0.75 | E32: =C32*D32 -> 0.75 | F32: 490 | G32: 500 | H32: g | I32: 10 | J32: 0 | K32: 0.015 | L32: 19, 24
A33: TOTAL COURSES RECETTES | E33: =SUM(E16:E32) -> 27.13 | J33: =SUM(J16:J32) -> 2.6259318 | K33: =SUM(K16:K32) -> 5.8723765
A34: Auchan Torsades à la carbonara 900 g | B34: Surgelé (week-end) | C34: 1 | D34: 4.95 | E34: =C34*D34 -> 4.95 | L34: Samedi soir + dimanche midi
A35: Auchan Pizza bolognaise 390 g | B35: Surgelé (week-end) | C35: 1 | D35: 2.05 | E35: =C35*D35 -> 2.05 | L35: Dimanche soir
A36: TOTAL PANIER (recettes + week-end) | E36: =E33+E34+E35 -> 34.13
A38: PLACARD / BASES utilisées cette semaine — comptées au PRIX PLEIN du format
A39: Produit exact | B39: Rayon | C39: Qté | D39: Prix format € | E39: Total € | F39: Qté utilisée cette semaine | G39: Contenu format | H39: Unité | I39: Reste (stock) | K39: Valeur du reste € | L39: Sert aux recettes
A40: Beurre | B40: Placard | C40: 1 | D40: 2.45 | E40: =C40*D40 -> 2.45 | F40: 10 | G40: 250 | H40: g | I40: 240 | K40: =D40*I40/G40 -> 2.352 | L40: 15
A41: Bouillon cube | B41: Placard | C41: 1 | D41: 1.79 | E41: =C41*D41 -> 1.79 | F41: 16 | G41: 180 | H41: g | I41: 164 | K41: =D41*I41/G41 -> 1.6308889 | L41: 9, 16
A42: Huile de tournesol | B42: Placard | C42: 1 | D42: 2.15 | E42: =C42*D42 -> 2.15 | F42: 60 | G42: 1000 | H42: ml | I42: 940 | K42: =D42*I42/G42 -> 2.021 | L42: 9, 16, 24
A43: Miel liquide | B43: Placard | C43: 1 | D43: 2.15 | E43: =C43*D43 -> 2.15 | F43: 10 | G43: 250 | H43: g | I43: 240 | K43: =D43*I43/G43 -> 2.064 | L43: 19
A44: Origan Ducros 12 g | B44: Placard | C44: 1 | D44: 1.89 | E44: =C44*D44 -> 1.89 | F44: 1 | G44: 12 | H44: g | I44: 11 | K44: =D44*I44/G44 -> 1.7325 | L44: 19
A45: Ras el hanout La Conquête des Saveurs 240 g | B45: Placard | C45: 1 | D45: 3.99 | E45: =C45*D45 -> 3.99 | F45: 14 | G45: 240 | H45: g | I45: 226 | K45: =D45*I45/G45 -> 3.75725 | L45: 16
A46: Sel / poivre | B46: Placard | C46: 1 | D46: 0.5 | E46: =C46*D46 -> 0.5 | F46: 12 | G46: 100 | H46: g | I46: 88 | K46: =D46*I46/G46 -> 0.44 | L46: 9, 15, 16, 19, 24
A47: TOTAL placard (prix plein) | E47: =SUM(E40:E46) -> 14.92
...

Sheet S5
A1: Semaine 5 — total 50.62 € (marge 4.38 €) — retrait Chronodrive le dimanche
A3: PLANNING
A4: Jour | B4: Midi | C4: Soir | D4: kcal / portion (soir) | E4: À cuisiner ce jour | F4: Note | G4: Macros / portion (P / G / L en g)
A5: Dimanche (retrait) | B5: libre / reste | C5: Pizza : Auchan Les Italiennes 4 fromages 340 g | D5: ≈ 900 | E5: Four 12 min | F5: Retrait du drive le matin
A6: Lundi | B6: Portion 2 de la pizza / reste | C6: 13. Tortellini aux champignons, sauce crème-parmesan | D6: =ROUND(Nutrition!H204,0) -> 888 | E6: 20 min (8 + 12) — 2 portions | F6: Lait supprimé (eau de cuisson) ; parmesan = grana padano. | G6: =ROUND(Nutrition!I204,0)&" / "&ROUND(Nutrition!J204,0)&" / "&ROUND(Nutrition!K204,0) -> 33 / 93 / 41
A7: Mardi | B7: Portion 2 de : Tortellini aux champignons, sauce crème-parmesan | C7: 21. Risotto de coquillettes au jambon, petits pois et parmesan | D7: =ROUND(Nutrition!H339,0) -> 738 | E7: 25 min (5 + 20) — 2 portions | F7: Mascarpone → crème épaisse. | G7: =ROUND(Nutrition!I339,0)&" / "&ROUND(Nutrition!J339,0)&" / "&ROUND(Nutrition!K339,0) -> 39 / 103 / 18
A8: Mercredi | B8: Portion 2 de : Risotto de coquillettes au jambon, petits pois et parmesan | C8: 5. Pâtes à la « carbonara » à la française | D8: =ROUND(Nutrition!H71,0) -> 876 | E8: 20 min (5 + 15) — 2 portions | G8: =ROUND(Nutrition!I71,0)&" / "&ROUND(Nutrition!J71,0)&" / "&ROUND(Nutrition!K71,0) -> 30 / 100 / 39
A9: Jeudi | B9: Portion 2 de : Pâtes à la « carbonara » à la française | C9: 14. Risotto aux lardons et champignons | D9: =ROUND(Nutrition!H221,0) -> 943 | E9: 36 min (annoncé) — ≈ 30 min réel — 2 portions | G9: =ROUND(Nutrition!I221,0)&" / "&ROUND(Nutrition!J221,0)&" / "&ROUND(Nutrition!K221,0) -> 29 / 96 / 48
A10: Vendredi | B10: Portion 2 de : Risotto aux lardons et champignons | C10: 20. One pot pasta chorizo-basilic | D10: =ROUND(Nutrition!H321,0) -> 944 | E10: 30 min (annoncé) — ≈ 25 min — 2 portions | G10: =ROUND(Nutrition!I321,0)&" / "&ROUND(Nutrition!J321,0)&" / "&ROUND(Nutrition!K321,0) -> 37 / 101 / 43
A11: Samedi | B11: Portion 2 de : One pot pasta chorizo-basilic | C11: ½ Auchan Riz cantonais 900 g | D11: ≈ 900-1 000 | E11: Poêle / micro-ondes | F11: Sachet coupé en 2 (congélateur)
A12: Dimanche midi | B12: ½ Auchan Riz cantonais 900 g | C12: → pizza de la semaine suivante
A14: LISTE DE COURSES CHRONODRIVE — formats entiers
A15: Produit exact (Chronodrive) | B15: Rayon | C15: Qté à acheter | D15: Prix unitaire € | E15: Total € | F15: Besoin semaine (2 portions x 5) | G15: Acheté | H15: Unité | I15: Reste après la semaine | J15: dont gâchis estimé € | K15: dont stock (se garde) € | L15: Sert aux recettes
A16: Auchan Terroir chorizo doux 225 g | B16: Charcuterie | C16: 1 | D16: 2.59 | E16: =C16*D16 -> 2.59 | F16: 150 | G16: 225 | H16: g | I16: 75 | J16: 0.259 | K16: 0.60433333 | L16: 20
A17: Herta Le Bon Paris 4 tranches 140 g | B17: Charcuterie | C17: 1 | D17: 2.59 | E17: =C17*D17 -> 2.59 | F17: 140 | G17: 140 | H17: g | I17: 0 | J17: 0 | K17: 0 | L17: 21
A18: Auchan lardons fumés 2 x 100 g | B18: Charcuterie | C18: 2 | D18: 2.09 | E18: =C18*D18 -> 4.18 | F18: 270 | G18: 400 | H18: g | I18: 130 | J18: 0.67925 | K18: 0.67925 | L18: 5, 14
A19: Auchan crème épaisse légère 15 % 20 cl | B19: Crèmerie | C19: 1 | D19: 0.75 | E19: =C19*D19 -> 0.75 | F19: 170 | G19: 200 | H19: ml | I19: 30 | J19: 0.03375 | K19: 0.07875 | L19: 13, 21
A20: Auchan crème fluide légère 15 % 3 x 20 cl | B20: Crèmerie | C20: 1 | D20: 1.99 | E20: =C20*D20 -> 1.99 | F20: 410 | G20: 600 | H20: ml | I20: 190 | J20: 0 | K20: 0.63016667 | L20: 5, 14
A21: Auchan Tavola grana padano râpé 120 g | B21: Crèmerie | C21: 1 | D21: 1.95 | E21: =C21*D21 -> 1.95 | F21: 110 | G21: 120 | H21: g | I21: 10 | J21: 0 | K21: 0.1625 | L21: 13, 14, 20, 21
A22: Auchan œufs plein air x6 | B22: Crèmerie | C22: 1 | D22: 1.69 | E22: =C22*D22 -> 1.69 | F22: 36 | G22: 330 | H22: g | I22: 294 | J22: 0 | K22: 1.5056364 | L22: 5
A23: Auchan Tavola tortellini 3 fromages 250 g | B23: Frais | C23: 2 | D23: 2.05 | E23: =C23*D23 -> 4.1 | F23: 400 | G23: 500 | H23: g | I23: 100 | J23: 0.82 | K23: 0 | L23: 13
A24: Oignon jaune 1 kg | B24: Fruits & légumes | C24: 1 | D24: 2.69 | E24: =C24*D24 -> 2.69 | F24: 460 | G24: 1000 | H24: g | I24: 540 | J24: 0.29052 | K24: 1.16208 | L24: 5, 13, 14, 20, 21
A25: Tomates cerises 250 g | B25: Fruits & légumes | C25: 1 | D25: 0.99 | E25: =C25*D25 -> 0.99 | F25: 150 | G25: 250 | H25: g | I25: 100 | J25: 0.396 | K25: 0 | L25: 20
A26: Auchan champignons émincés boîte 230 g égoutté | B26: Épicerie | C26: 2 | D26: 1.29 | E26: =C26*D26 -> 2.58 | F26: 400 | G26: 460 | H26: g | I26: 60 | J26: 0.33652174 | K26: 0 | L26: 13, 14
A27: Auchan coquillettes 500 g | B27: Épicerie | C27: 1 | D27: 0.85 | E27: =C27*D27 -> 0.85 | F27: 250 | G27: 500 | H27: g | I27: 250 | J27: 0 | K27: 0.425 | L27: 21
... A30: Auchan spaghetti 500 g | B30: Épicerie | C30: 1 | D30: 0.75 | E30: =C30*D30 -> 0.75 | F30: 500 | G30: 500 | H30: g | I30: 0 | J30: 0 | K30: 0 | L30: 5, 20
A31: TOTAL COURSES RECETTES | E31: =SUM(E16:E30) -> 30.64 | J31: =SUM(J16:J30) -> 3.1223049 | K31: =SUM(K16:K30) -> 6.8326637
A32: Auchan Riz cantonais 900 g | B32: Surgelé (week-end) | C32: 1 | D32: 4.65 | E32: =C32*D32 -> 4.65 | L32: Samedi soir + dimanche midi
A33: Auchan Les Italiennes 4 fromages 340 g | B33: Surgelé (week-end) | C33: 1 | D33: 2.55 | E33: =C33*D33 -> 2.55 | L33: Dimanche soir
A34: TOTAL PANIER (recettes + week-end) | E34: =E31+E32+E33 -> 37.84
A36: PLACARD / BASES utilisées cette semaine — comptées au PRIX PLEIN du format
A37: Produit exact | B37: Rayon | C37: Qté | D37: Prix format € | E37: Total € | F37: Qté utilisée cette semaine | G37: Contenu format | H37: Unité | I37: Reste (stock) | K37: Valeur du reste € | L37: Sert aux recettes
